<?xml version="1.0" encoding="UTF-8"?>
<robot xmlns:xacro="http://www.ros.org/wiki/xacro" name="hector_tracker_sensor_head">
    
  <xacro:include filename="$(find hector_xacro_tools)/urdf/inertia_tensors.urdf.xacro" />
  <xacro:include filename="$(find hector_xacro_tools)/urdf/joint_macros.urdf.xacro" />
  <xacro:include filename="$(find hector_sensors_description)/urdf/realsense_d435_camera.urdf.xacro" />
  <xacro:include filename="$(find hector_sensors_description)/urdf/seek_thermal_compact.urdf.xacro" />
  
  <xacro:macro name="xm430_sensor_head_macro" params="parent *origin name">
    <xacro:arg name="add_raycast_self_filter_geom" default="false" />
    
    <joint name="${name}_mount_joint" type="fixed">
      <xacro:insert_block name="origin" />
      <parent link="${parent}" />
      <child link="${name}_mount_link" />
    </joint>
    
    <link name="${name}_mount_link">
      <xacro:inertial_sphere mass="0.09" diameter="0.05" />
      <visual>
        <origin xyz="0.0 -0.01 0.017" rpy="0 0 0" />
        <geometry>
          <box size="0.0285 0.07 0.034" />
        </geometry>
        <material name="DarkGrey" />
      </visual>
      
      <collision>
        <origin xyz="0.0 -0.01 0.017" rpy="0 0 0" />
        <geometry>
          <box size="0.0285 0.07 0.034" />
        </geometry>
      </collision>
      
      <xacro:if value="$(arg add_raycast_self_filter_geom)">
        <collision>
          <origin xyz="0.0 -0.01 0.017" rpy="${M_PI*0.5} 0 0" />
          <geometry>
            <cylinder length="0.07" radius="0.022"/>
          </geometry>
        </collision>
      </xacro:if>
    </link>
    
    <joint name="sensor_head_yaw_joint" type="revolute">
      <origin xyz="0.0 0.0 0.0" rpy="0 0 0" />
      <parent link="${name}_mount_link" />
      <child link="sensor_head_yaw_link" />
      <axis xyz="0 0 1" />
      <limit lower="${-M_PI/2}" upper="${M_PI/2}" effort="4" velocity="4.81710873" />
    </joint>
    
    <link name="sensor_head_yaw_link">
      <xacro:inertial_sphere mass="0.09" diameter="0.07" />
      <visual>
        <origin xyz="0.0 0.0 0.0625" rpy="0 0 0" />
        <geometry>
          <box size="0.0285 0.034 0.055" />
        </geometry>
        <material name="DarkGrey" />
      </visual>
      
      <collision>
        <origin xyz="0.0 0.0 0.0625" rpy="0 0 0" />
        <geometry>
          <box size="0.0285 0.034 0.055" />
        </geometry>
      </collision>
      
      <xacro:if value="$(arg add_raycast_self_filter_geom)">
        <collision>
          <origin xyz="0.0 0.0 0.0625" rpy="0 0 0" />
          <geometry>
            <cylinder length="0.055" radius="0.022"/>
          </geometry>
        </collision>
      </xacro:if>
    </link>
    
    <joint name="sensor_head_pitch_joint" type="revolute">
      <origin xyz="0.0 0.0 0.075" rpy="${-M_PI/2} 0 0" />
      <parent link="sensor_head_yaw_link" />
      <child link="sensor_head_pitch_link" />
      <axis xyz="0 0 1" />
      <limit lower="${-M_PI/2}" upper="${M_PI/2}" effort="4" velocity="4.81710873" />
    </joint>
    
    <link name="sensor_head_pitch_link">
      <xacro:inertial_sphere mass="0.03" diameter="0.07" />
      <visual>
        <origin xyz="0.0 -0.0255 0.0" rpy="0 0 0" />
        <geometry>
          <box size="0.025 0.005 0.045" />
        </geometry>
        <material name="DarkGrey" />
      </visual>
      <visual>
        <origin xyz="0.0 -0.0075 0.02" rpy="0 0 0" />
        <geometry>
          <box size="0.025 0.035 0.006" />
        </geometry>
        <material name="DarkGrey" />
      </visual>
      <visual>
        <origin xyz="0.0 -0.0075 -0.02" rpy="0 0 0" />
        <geometry>
          <box size="0.025 0.035 0.006" />
        </geometry>
        <material name="DarkGrey" />
      </visual>
      
      <collision>
        <origin xyz="0.0 -0.0075 0.0" rpy="0 0 0" />
        <geometry>
          <box size="0.025 0.035 0.045" />
        </geometry>
      </collision>
      
      <xacro:if value="$(arg add_raycast_self_filter_geom)">
        <collision>
          <origin xyz="0.0 -0.0075 0.0" rpy="0 0 0" />
          <geometry>
            <cylinder length="0.045" radius="0.022"/>
          </geometry>
        </collision>
      </xacro:if>
    </link>

    <gazebo reference="sensor_head_yaw_link">
      <material>Gazebo/Grey</material>
    </gazebo>
    
    <gazebo reference="sensor_head_pitch_link">
      <material>Gazebo/Grey</material>
    </gazebo>
    
    <gazebo reference="sensor_head_mount_link">
      <material>Gazebo/Grey</material>
    </gazebo>
    
    <xacro:joint_standard_transmission name="sensor_head_yaw_joint" />
    <xacro:joint_standard_transmission name="sensor_head_pitch_joint" />
    
    <gazebo>
      <plugin name="gazebo_ros_control_select_joints" filename="libgazebo_ros_control_select_joints.so">
        <robotNamespace>sensor_head_control</robotNamespace>
        <joints>sensor_head_yaw_joint sensor_head_pitch_joint</joints>
      </plugin>
    </gazebo>
    
    <xacro:seek_thermal_compact_camera name="arm_thermal_cam" parent="sensor_head_pitch_link">
      <origin xyz="-0.01 -0.07 0" rpy="${0.5*M_PI} 0 0" />
    </xacro:seek_thermal_compact_camera>
    
    <xacro:realsense_d435_camera_comprehensive_params name="arm_rgbd_cam" parent="sensor_head_pitch_link" image_topic="image_rect_color" depth_points_topic="depth/points" min_range="0.3" max_range="9.0" update_rate="20">
      <origin xyz="0.0253 -0.0445 0.0175" rpy="${M_PI*0.5} 0.0 0.0" />
    </xacro:realsense_d435_camera_comprehensive_params>
    
  </xacro:macro>
</robot>